Workbook

Sheet Start Here
A1: Task App Setup Worksheet
A2: While you set up the course's full-stack task app, you create accounts on several websites (Supabase, Google Cloud, OpenAI, Stripe, Vercel) and collect IDs, web addresses and keys. This workbook keeps them in one place and builds the exact lines you copy into your project.
A3: How the workbook works
A4: 1. My Info: one row for each thing you record. Fill in the yellow cells as you go, following the course notes. The Example column shows what a value looks like (the examples are fake). Type Yes in the Done column when a row is finished.
A5: 2. Commands: you never type here. Its formulas combine your My Info values into the lines you need: the two lines of .env.local, the terminal commands, the SQL for Supabase Vault, and the addresses you paste into Google, Supabase, Stripe and Vercel. A line shows "(fill in ... first)" until the values it needs are on My Info.
A6: 3. To use a line: click its cell in the "Copy this" column, copy (Cmd+C on a Mac, Ctrl+C on Windows and Linux), and paste it where the Where column says. When you paste a command into the terminal it may run right away; that is fine. When you paste into a website's form, delete any space or blank line that comes along at the end.
A7: A word you'll see: OAuth
A8: OAuth is the standard behind "Sign in with Google": the user signs in at Google, and Google tells your app who they are, without your app ever seeing their password. The Google rows and the Google callback URL are your app's OAuth settings.
A9: Read more: OAuth in the course book (click)
A10: Colors
A11: Yellow cell: you type a value here.
A12: Gray cell: filled in for you by a formula. Don't type here.
... A21: - At the end of the semester, delete the keys on each website, then delete this file.

Sheet My Info
A1: My Info: fill in the yellow cells as you go | E1: ="Done: "&COUNTIF(G5:G42,"Yes")&" of 26 rows" -> Done: 0 of 26 rows
A2: Yellow = you type here. Gray = filled in for you. Examples are fake and only show the format. Keep this file outside your project folder.
A4: What to record | B4: Example (fake) | C4: Your value | D4: Secret? | E4: Where to find it | F4: Where you use it | G4: Done?
A5: Your computer
A6: Your computer: Mac, Windows or Linux | B6: Mac | E6: Choose from the list. | F6: Tells you which tab to follow in the course notes.
A7: The app's code folder (task-app) on your computer | B7: /Users/maria/projects/full-stack-demo-app/task-app (Windows: /c/Users/sam/projects/full-stack-demo-app/task-app; Linux: /home/alex/projects/full-stack-demo-app/task-app) | E7: In the terminal, cd into the project folder and run pwd. | F7: Run every npx and npm command from this folder (cd into it first).
A8: GitHub
A9: GitHub username | B9: maria-lopez | D9: public | E9: github.com, click your picture (top right). | F9: Part of your fork's address.
A10: Your fork's address (filled in for you) | C10: =IF('My Info'!$C$9="","","https://github.com/"&'My Info'!$C$9&"/task-app") | D10: public | E10: Built from your GitHub username (name your fork task-app when you create it). | F10: git clone (see the Commands sheet).
A11: Supabase (database, login, file storage, Edge Functions)
A12: Email you use to sign in to Supabase | B12: maria@example.com | E12: supabase.com (signing in with GitHub is easiest). | F12: Signing in to the Supabase dashboard.
A13: Supabase project name | B13: task-app-2026-maria | E13: You choose it when you create the project. | F13: Finding your project in the dashboard.
A14: Database password | B14: (a long random password) | D14: SECRET | E14: You choose it when you create the project (use the Generate button). It is shown only then. | F14: The Supabase CLI may ask for it (npx supabase link, npx supabase db push).
A15: Project ref (Project ID) | B15: abcdefghijklmnopqrst | D15: public | E15: Project Settings > General > Project ID. It is also the part of your project URL before .supabase.co. | F15: npx supabase link; it builds the URLs below.
A16: Project URL (filled in for you) | C16: =IF('My Info'!$C$15="","","https://"&'My Info'!$C$15&".supabase.co") | D16: public | E16: Built from the project ref. Check it against the URL in the dashboard. | F16: .env.local (NEXT_PUBLIC_SUPABASE_URL) and Vercel.
A17: Publishable key | B17: sb_publishable_AbCdEf123... | D17: public | E17: Project Settings > API Keys, under Publishable key. Click the copy icon next to it: the page shows only the start of the key. | F17: .env.local (NEXT_PUBLIC_SUPABASE_PUBLISHABLE_KEY) and Vercel. Safe in a web page, but don't post it.
A18: Secret key. Only for the optional tests. | B18: sb_secret_AbCdEf123... | D18: SECRET | E18: Project Settings > API Keys, under Secret keys. Click the copy icon next to it (the eye icon shows the key). | F18: .env.test.local only. Never in .env.local, never in Vercel: it bypasses all security.
A19: Google sign-in (OAuth) callback URL (filled in for you) | C19: =IF('My Info'!$C$15="","",'My Info'!$C$16&"/auth/v1/callback") | D19: public | E19: Built from the project URL. Supabase also shows it on the Google provider page, as Callback URL (for OAuth). | F19: Google Cloud: Authorized redirect URI.
A20: Stripe webhook URL (filled in for you) | C20: =IF('My Info'!$C$15="","",'My Info'!$C$16&"/functions/v1/stripe-webhook") | D20: public | E20: Built from the project URL. | F20: Stripe: the webhook endpoint (event destination) URL.
A21: Your project's dashboard (filled in for you) | C21: =IF('My Info'!$C$15="","","https://supabase.com/dashboard/project/"&'My Info'!$C$15) | D21: public | E21: Built from the project ref. | F21: Bookmark it.
A22: Google ("Sign in with Google", i.e. OAuth)
A23: Google account you use for Google Cloud | B23: maria.lopez@gmail.com | E23: console.cloud.google.com | F23: Signing in to Google Cloud Console.
A24: Google Cloud project name | B24: task-app-2026-maria | E24: You choose it when you create the project. | F24: Finding the project in Google Cloud Console.
A25: OAuth Client ID | B25: 123456789012-abc123def456.apps.googleusercontent.com | D25: public | E25: Google Auth Platform > Clients > Create client (Web application). | F25: Supabase: Authentication > Sign In / Providers > Google.
A26: OAuth Client secret | B26: GOCSPX-AbCdEf123... | D26: SECRET | E26: Shown in full only when you create the client. Copy it right away (or download the JSON file). | F26: Supabase: Authentication > Sign In / Providers > Google.
A27: OpenAI (AI task labels; about $5 of prepaid credit)
A28: Email you use to sign in to OpenAI | B28: maria@example.com | E28: platform.openai.com | F28: Signing in to the OpenAI API platform.
A29: Credit you bought ($) | B29: 5 | E29: Organization settings > Billing > Buy credits (first time: Add payment details). Keep auto-reload OFF. | F29: Your total budget. With auto-reload off, OpenAI never charges your card again on its own.
A30: OpenAI project name | B30: task-app-2026-maria | E30: Create it from the project menu at the top left of platform.openai.com. | F30: Keeps this app's key and spending separate.
A31: Monthly spend limit you set for the project ($) | B31: 5 | E31: Settings > Limits > Set spend limit. Turn ON "Enforce a hard limit". | F31: With the hard limit on, OpenAI refuses requests once the project reaches it.
A32: OpenAI API key | B32: sk-proj-AbCdEf123... | D32: SECRET | E32: Inside your project: API keys > Create new secret key. Shown only once. | F32: npx supabase secrets set OPENAI_API_KEY=... (see the Commands sheet).
A33: Stripe (payments, test mode only: no real money)
A34: Email you use to sign in to Stripe | B34: maria@example.com | E34: dashboard.stripe.com | F34: Signing in to Stripe.
A35: Publishable key (test mode) | B35: pk_test_51AbCd... | D35: public | E35: Stripe dashboard home page, or dashboard.stripe.com/apikeys (in your sandbox). | F35: Not used by this app's code. Record it anyway.
A36: Secret key (test mode) | B36: sk_test_51AbCd... | D36: SECRET | E36: Stripe dashboard home page, or dashboard.stripe.com/apikeys (in your sandbox). Click to reveal. | F36: Supabase secret STRIPE_SECRET_KEY, Supabase Vault (named stripe), .env.test.local.
A37: Product name | B37: TaskMaster Premium | E37: You choose it when you create the product (Product catalog). | F37: Shows on the checkout page.
A38: Price ID of the monthly price | B38: price_1AbCdEf... | D38: public | E38: Product catalog > your product > click the price. The ID starts with price_. | F38: Supabase secret STRIPE_PRICE_ID, .env.test.local.
A39: Webhook signing secret | B39: whsec_AbCdEf123... | D39: SECRET | E39: dashboard.stripe.com/webhooks > your event destination > Signing secret > Reveal. | F39: Supabase secret STRIPE_WEBHOOK_SECRET, .env.test.local.
A40: Vercel (putting the app online, at the end)
A41: How you sign in to Vercel | B41: Continue with GitHub | E41: vercel.com (signing in with GitHub is easiest). | F41: Signing in to Vercel.
...

Sheet Commands
A1: Commands: copy a line from the "Copy this" column and paste it where the Where column says
A2: Don't type on this sheet: every line is built from your values on My Info. Copy one cell at a time.
A4: Where | B4: What it does | C4: Copy this
A5: 1. Copy your fork to your computer (terminal, in your project folder: cd ~/projects/full-stack-demo-app)
A6: Terminal | B6: Clone your fork | C6: =IF('My Info'!$C$9="","(fill in GitHub username on My Info first)","git clone "&'My Info'!$C$10) -> (fill in GitHub username on My Info first)
A7: 2. The file task-app/.env.local (open it in VS Code; one line per row, copy each line into the file)
A8: .env.local | B8: Line 1 | C8: =IF('My Info'!$C$15="","(fill in Project ref on My Info first)","NEXT_PUBLIC_SUPABASE_URL="&CHAR(34)&'My Info'!$C$16&CHAR(34)) -> (fill in Project ref on My Info first)
A9: .env.local | B9: Line 2 | C9: =IF('My Info'!$C$17="","(fill in Supabase publishable key on My Info first)","NEXT_PUBLIC_SUPABASE_PUBLISHABLE_KEY="&CHAR(34)&'My Info'!$C$17&CHAR(34)) -> (fill in Supabase publishable key on My Info first)
A10: 3. Terminal commands for the app (VS Code's terminal; start with the cd line)
A11: Terminal | B11: Go into the app's folder first (each new terminal starts in full-stack-demo-app) | C11: ="cd ~/projects/full-stack-demo-app/task-app" -> cd ~/projects/full-stack-demo-app/task-app
A12: Terminal | B12: Update the Supabase CLI first (the project pins an old version) | C12: ="npm install -D supabase@latest" -> npm install -D supabase@latest
A13: Terminal | B13: Sign in (opens your browser) | C13: ="npx supabase login" -> npx supabase login
A14: Terminal | B14: Connect this folder to your project | C14: =IF('My Info'!$C$15="","(fill in Project ref on My Info first)","npx supabase link --project-ref "&'My Info'!$C$15) -> (fill in Project ref on My Info first)
A15: Terminal | B15: Create the tables, storage bucket and security rules | C15: ="npx supabase db push" -> npx supabase db push
A16: Terminal | B16: Give the Edge Functions your OpenAI key | C16: =IF('My Info'!$C$32="","(fill in OpenAI API key on My Info first)","npx supabase secrets set OPENAI_API_KEY="&'My Info'!$C$32) -> (fill in OpenAI API key on My Info first)
A17: Terminal | B17: Give the Edge Functions your Stripe secret key | C17: =IF('My Info'!$C$36="","(fill in Stripe secret key on My Info first)","npx supabase secrets set STRIPE_SECRET_KEY="&'My Info'!$C$36) -> (fill in Stripe secret key on My Info first)
A18: Terminal | B18: Give the Edge Functions your Stripe price ID | C18: =IF('My Info'!$C$38="","(fill in Stripe price ID on My Info first)","npx supabase secrets set STRIPE_PRICE_ID="&'My Info'!$C$38) -> (fill in Stripe price ID on My Info first)
A19: Terminal | B19: Give the webhook its signing secret (after you create the webhook in Stripe) | C19: =IF('My Info'!$C$39="","(fill in Stripe webhook signing secret on My Info first)","npx supabase secrets set STRIPE_WEBHOOK_SECRET="&'My Info'!$C$39) -> (fill in Stripe webhook signing secret on My Info first)
A20: Terminal | B20: Deploy Edge Function 1 of 3 | C20: ="npx supabase functions deploy create-task-with-ai" -> npx supabase functions deploy create-task-with-ai
A21: Terminal | B21: Deploy Edge Function 2 of 3 | C21: ="npx supabase functions deploy create-stripe-session" -> npx supabase functions deploy create-stripe-session
A22: Terminal | B22: Deploy Edge Function 3 of 3 (Stripe calls it, so it must not require a login) | C22: ="npx supabase functions deploy stripe-webhook --no-verify-jwt" -> npx supabase functions deploy stripe-webhook --no-verify-jwt
A23: 4. Supabase SQL Editor (dashboard > SQL Editor > New query; paste, then click Run)
A24: SQL Editor | B24: Store the Stripe secret key in Supabase Vault, named stripe | C24: =IF('My Info'!$C$36="","(fill in Stripe secret key on My Info first)","select vault.create_secret('"&'My Info'!$C$36&"', 'stripe');") -> (fill in Stripe secret key on My Info first)
A25: 5. Paste into websites
A26: Google Cloud | B26: Client > Authorized JavaScript origins (local) | C26: ="http://localhost:3000" -> http://localhost:3000
A27: Google Cloud | B27: Client > Authorized redirect URIs | C27: =IF('My Info'!$C$15="","(fill in Project ref on My Info first)",'My Info'!$C$19) -> (fill in Project ref on My Info first)
A28: Supabase | B28: Authentication > URL Configuration > Site URL (while you work locally) | C28: ="http://localhost:3000" -> http://localhost:3000
A29: Supabase | B29: Authentication > URL Configuration > Redirect URLs (local) | C29: ="http://localhost:3000/**" -> http://localhost:3000/**
A30: Stripe | B30: Webhook event destination > Endpoint URL (payload style: Snapshot) | C30: =IF('My Info'!$C$15="","(fill in Project ref on My Info first)",'My Info'!$C$20) -> (fill in Project ref on My Info first)
A31: 6. After you deploy to Vercel
A32: Vercel | B32: Environment variable NEXT_PUBLIC_SUPABASE_URL (value) | C32: =IF('My Info'!$C$15="","(fill in Project ref on My Info first)",'My Info'!$C$16) -> (fill in Project ref on My Info first)
A33: Vercel | B33: Environment variable NEXT_PUBLIC_SUPABASE_PUBLISHABLE_KEY (value) | C33: =IF('My Info'!$C$17="","(fill in Supabase publishable key on My Info first)",'My Info'!$C$17) -> (fill in Supabase publishable key on My Info first)
A34: Supabase | B34: Authentication > URL Configuration > Site URL (once the app is online) | C34: =IF('My Info'!$C$42="","(fill in your Vercel address on My Info first)",'My Info'!$C$42) -> (fill in your Vercel address on My Info first)
A35: Supabase | B35: Authentication > URL Configuration > Redirect URLs (add this one too) | C35: =IF('My Info'!$C$42="","(fill in your Vercel address on My Info first)",'My Info'!$C$42&"/**") -> (fill in your Vercel address on My Info first)
A36: Google Cloud | B36: Client > Authorized JavaScript origins (add this one too) | C36: =IF('My Info'!$C$42="","(fill in your Vercel address on My Info first)",'My Info'!$C$42) -> (fill in your Vercel address on My Info first)
A37: 7. Optional: task-app/.env.test.local for the automated tests (one line per row)
A38: .env.test.local | B38: Line 1 | C38: =IF('My Info'!$C$15="","(fill in Project ref on My Info first)","NEXT_PUBLIC_SUPABASE_URL="&CHAR(34)&'My Info'!$C$16&CHAR(34)) -> (fill in Project ref on My Info first)
A39: .env.test.local | B39: Line 2 | C39: =IF('My Info'!$C$17="","(fill in Supabase publishable key on My Info first)","NEXT_PUBLIC_SUPABASE_PUBLISHABLE_KEY="&CHAR(34)&'My Info'!$C$17&CHAR(34)) -> (fill in Supabase publishable key on My Info first)
A40: .env.test.local | B40: Line 3 | C40: =IF('My Info'!$C$18="","(fill in Supabase secret key on My Info first)","SUPABASE_SECRET_KEY="&CHAR(34)&'My Info'!$C$18&CHAR(34)) -> (fill in Supabase secret key on My Info first)
A41: .env.test.local | B41: Line 4 | C41: =IF('My Info'!$C$36="","(fill in Stripe secret key on My Info first)","STRIPE_SECRET_KEY="&CHAR(34)&'My Info'!$C$36&CHAR(34)) -> (fill in Stripe secret key on My Info first)
...
